Running docker-compose command "ps --services --filter status=running"
Running docker-compose command "exec nautobot coverage run --module nautobot.core.cli test nautobot.extras.tests --config=nautobot/core/tests/nautobot_config.py --keepdb --buffer"
PYTHON_VER=3.10 \
docker-compose \
    --project-name "nautobot" \
    --project-directory "development" \
    -f "development/docker-compose.yml" \
    -f "development/docker-compose.postgres.yml" \
    -f "development/docker-compose.dev.yml" exec nautobot coverage run \
    --module nautobot.core.cli test nautobot.extras.tests \
    --config=nautobot/core/tests/nautobot_config.py \
    --keepdb \
    --buffer
Using NautobotPerformanceTestRunner to run tests ...
Using existing test database for alias 'default'...
Pre-populating test database with factory data...
[33;1mFlushing all existing data from the database...[0m
Seeding the pseudo-random number generator with seed "Nautobot"...
Creating Roles...
Creating Statuses...
Creating Tags...
Creating TenantGroups...
Creating Tenants...
Creating LocationTypes...
Creating Locations...
Creating RIRs...
Creating RouteTargets...
Creating VRFs...
Creating VLANGroups...
Creating VLANs...
Creating Prefixes and IP Addresses...
Creating Manufacturers...
Creating Platforms (with manufacturers)...
Creating Platforms (without manufacturers)...
Creating Manufacturers without platforms...
Creating DeviceTypes...
Creating DeviceRedundancyGroups...
Creating CircuitTypes...
Creating Providers...
Creating ProviderNetworks...
Creating Circuits...
Creating Providers without Circuits...
Creating CircuitTerminations...
[32;1mDatabase populated successfully![0m
System check identified some issues:

WARNINGS:
[33;1m<Settings "nautobot_config">: (nautobot.core.W005) STORAGE_CONFIG has been set but STORAGE_BACKEND is not defined. STORAGE_CONFIG will be ignored.[0m

System check identified 1 issue (0 silenced).
................................................F..F...................F................F.....................s......................s......................s.....................F..F.................................................s....................................................s...............................................................................................FF.F....FFF....................................s.....F...............F........................FF.....................................................................................................................................FF......................s...........................F......F.................FFFFFF..FF.FF.............................................................................................s....s.....s........s.......s....s....s..s..s.s....s....s....s..s........s....s...s...s.s.....s.....s..............s.....s....s......s.s...s...s...s.....s......s..s........s..s.....s....s....s..s.............s.s....s...s....s...s.....s....s....s.................................................................................................................................................E.........................................................................................................................................FF..........................s............................s..................................s..................................s................................s...........................s...............................s..........................s.............................................................s..........................s.......................s.........................s....................................................s............................s..............................................................s.............................................................................................................................................................s.........................................................
======================================================================
ERROR: test_get_notes_url_on_object_raise_no_reverse_match (nautobot.extras.tests.test_plugins.PluginAPITest)
----------------------------------------------------------------------
Traceback (most recent call last):
  File "/usr/local/lib/python3.10/site-packages/django/test/utils.py", line 387, in inner
    return func(*args, **kwargs)
  File "/usr/local/lib/python3.10/unittest/mock.py", line 1376, in patched
    with self.decoration_helper(patched,
  File "/usr/local/lib/python3.10/contextlib.py", line 135, in __enter__
    return next(self.gen)
  File "/usr/local/lib/python3.10/unittest/mock.py", line 1358, in decoration_helper
    arg = exit_stack.enter_context(patching)
  File "/usr/local/lib/python3.10/contextlib.py", line 492, in enter_context
    result = _cm_type.__enter__(cm)
  File "/usr/local/lib/python3.10/unittest/mock.py", line 1447, in __enter__
    original, local = self.get_original()
  File "/usr/local/lib/python3.10/unittest/mock.py", line 1420, in get_original
    raise AttributeError(
AttributeError: <module 'nautobot.extras.api.serializers' from '/source/nautobot/extras/api/serializers.py'> does not have the attribute 'reverse'


======================================================================
FAIL: test_run_job_file_data_schedule (nautobot.extras.tests.test_api.JobTest)
Job run requests can reference objects by their attributes.
----------------------------------------------------------------------
Traceback (most recent call last):
  File "/usr/local/lib/python3.10/site-packages/django/test/utils.py", line 387, in inner
    return func(*args, **kwargs)
  File "/usr/local/lib/python3.10/unittest/mock.py", line 1379, in patched
    return func(*newargs, **newkeywargs)
  File "/source/nautobot/extras/tests/test_api.py", line 1566, in test_run_job_file_data_schedule
    self.assertHttpStatus(response, self.run_success_response_status)
  File "/source/nautobot/core/testing/mixins.py", line 166, in assertHttpStatus
    self.assertIn(response.status_code, expected_status, err_message)
AssertionError: 500 not found in [201] : Expected HTTP status(es) [201]; received 500: {"error": "Object of type NautobotFakeRequest is not JSON serializable", "exception": "TypeError", "nautobot_version": "2.0.0a1", "python_version": "3.10.10"}

======================================================================
FAIL: test_run_job_future (nautobot.extras.tests.test_api.JobTest)
In addition to the base test case provided by JobAPIRunTestMixin, also verify the JSON response data.
----------------------------------------------------------------------
Traceback (most recent call last):
  File "/usr/local/lib/python3.10/site-packages/django/test/utils.py", line 387, in inner
    return func(*args, **kwargs)
  File "/usr/local/lib/python3.10/unittest/mock.py", line 1379, in patched
    return func(*newargs, **newkeywargs)
  File "/source/nautobot/extras/tests/test_api.py", line 1587, in test_run_job_future
    self.assertHttpStatus(response, self.run_success_response_status)
  File "/source/nautobot/core/testing/mixins.py", line 166, in assertHttpStatus
    self.assertIn(response.status_code, expected_status, err_message)
AssertionError: 500 not found in [201] : Expected HTTP status(es) [201]; received 500: {"error": "Object of type NautobotFakeRequest is not JSON serializable", "exception": "TypeError", "nautobot_version": "2.0.0a1", "python_version": "3.10.10"}

======================================================================
FAIL: test_run_job_interval (nautobot.extras.tests.test_api.JobTest)
----------------------------------------------------------------------
Traceback (most recent call last):
  File "/usr/local/lib/python3.10/site-packages/django/test/utils.py", line 387, in inner
    return func(*args, **kwargs)
  File "/usr/local/lib/python3.10/unittest/mock.py", line 1379, in patched
    return func(*newargs, **newkeywargs)
  File "/source/nautobot/extras/tests/test_api.py", line 1728, in test_run_job_interval
    self.assertHttpStatus(response, self.run_success_response_status)
  File "/source/nautobot/core/testing/mixins.py", line 166, in assertHttpStatus
    self.assertIn(response.status_code, expected_status, err_message)
AssertionError: 500 not found in [201] : Expected HTTP status(es) [201]; received 500: {"error": "Object of type NautobotFakeRequest is not JSON serializable", "exception": "TypeError", "nautobot_version": "2.0.0a1", "python_version": "3.10.10"}

======================================================================
FAIL: test_run_job_object_var (nautobot.extras.tests.test_api.JobTest)
Job run requests can reference objects by their primary keys.
----------------------------------------------------------------------
Traceback (most recent call last):
  File "/usr/local/lib/python3.10/site-packages/django/test/utils.py", line 387, in inner
    return func(*args, **kwargs)
  File "/usr/local/lib/python3.10/unittest/mock.py", line 1379, in patched
    return func(*newargs, **newkeywargs)
  File "/source/nautobot/extras/tests/test_api.py", line 1384, in test_run_job_object_var
    self.assertHttpStatus(response, self.run_success_response_status)
  File "/source/nautobot/core/testing/mixins.py", line 166, in assertHttpStatus
    self.assertIn(response.status_code, expected_status, err_message)
AssertionError: 500 not found in [201] : Expected HTTP status(es) [201]; received 500: {"error": "Object of type NautobotFakeRequest is not JSON serializable", "exception": "TypeError", "nautobot_version": "2.0.0a1", "python_version": "3.10.10"}

======================================================================
FAIL: test_run_job_object_var_lookup (nautobot.extras.tests.test_api.JobTest)
Job run requests can reference objects by their attributes.
----------------------------------------------------------------------
Traceback (most recent call last):
  File "/usr/local/lib/python3.10/site-packages/django/test/utils.py", line 387, in inner
    return func(*args, **kwargs)
  File "/usr/local/lib/python3.10/unittest/mock.py", line 1379, in patched
    return func(*newargs, **newkeywargs)
  File "/source/nautobot/extras/tests/test_api.py", line 1489, in test_run_job_object_var_lookup
    self.assertEqual(data_job_result, expected_data_job_result)
AssertionError: {'id'[90 chars]', 'computed_fields': {}, 'custom_fields': {},[2444 chars]None} != {'id'[90 chars]', 'custom_fields': {}, 'status': OrderedDict([2313 chars]None}

======================================================================
FAIL: test_run_job_object_var_no_schedule (nautobot.extras.tests.test_api.JobTest)
Run a job with `approval_required` without providing a schedule.
----------------------------------------------------------------------
Traceback (most recent call last):
  File "/usr/local/lib/python3.10/site-packages/django/test/utils.py", line 387, in inner
    return func(*args, **kwargs)
  File "/usr/local/lib/python3.10/unittest/mock.py", line 1379, in patched
    return func(*newargs, **newkeywargs)
  File "/source/nautobot/extras/tests/test_api.py", line 1432, in test_run_job_object_var_no_schedule
    self.assertHttpStatus(response, self.run_success_response_status)
  File "/source/nautobot/core/testing/mixins.py", line 166, in assertHttpStatus
    self.assertIn(response.status_code, expected_status, err_message)
AssertionError: 500 not found in [201] : Expected HTTP status(es) [201]; received 500: {"error": "Object of type NautobotFakeRequest is not JSON serializable", "exception": "TypeError", "nautobot_version": "2.0.0a1", "python_version": "3.10.10"}

======================================================================
FAIL: test_get_association_data_on_location (nautobot.extras.tests.test_api.RelationshipAssociationTest)
Check that `include=relationships` query parameter on a model endpoint includes relationships/associations.
----------------------------------------------------------------------
Traceback (most recent call last):
  File "/source/nautobot/extras/tests/test_api.py", line 2908, in test_get_association_data_on_location
    self.assertHttpStatus(response, status.HTTP_200_OK)
  File "/source/nautobot/core/testing/mixins.py", line 166, in assertHttpStatus
    self.assertIn(response.status_code, expected_status, err_message)
AssertionError: 500 not found in [200] : Expected HTTP status(es) [200]; received 500: {"error": "maximum recursion depth exceeded", "exception": "RecursionError", "nautobot_version": "2.0.0a1", "python_version": "3.10.10"}

======================================================================
FAIL: test_update_association_data_on_location (nautobot.extras.tests.test_api.RelationshipAssociationTest)
Check that relationship-associations can be updated via the 'relationships' field.
----------------------------------------------------------------------
Traceback (most recent call last):
  File "/source/nautobot/extras/tests/test_api.py", line 2976, in test_update_association_data_on_location
    self.assertHttpStatus(initial_response, status.HTTP_200_OK)
  File "/source/nautobot/core/testing/mixins.py", line 166, in assertHttpStatus
    self.assertIn(response.status_code, expected_status, err_message)
AssertionError: 500 not found in [200] : Expected HTTP status(es) [200]; received 500: {"error": "maximum recursion depth exceeded", "exception": "RecursionError", "nautobot_version": "2.0.0a1", "python_version": "3.10.10"}

======================================================================
FAIL: test_populate_relationship_associations_on_location_create (nautobot.extras.tests.test_api.RelationshipTest)
Verify that relationship associations can be populated at instance creation time.
----------------------------------------------------------------------
Traceback (most recent call last):
  File "/source/nautobot/extras/tests/test_api.py", line 2579, in test_populate_relationship_associations_on_location_create
    self.assertHttpStatus(response, status.HTTP_201_CREATED)
  File "/source/nautobot/core/testing/mixins.py", line 166, in assertHttpStatus
    self.assertIn(response.status_code, expected_status, err_message)
AssertionError: 500 not found in [201] : Expected HTTP status(es) [201]; received 500: {"error": "'NoneType' object has no attribute 'Meta'", "exception": "AttributeError", "nautobot_version": "2.0.0a1", "python_version": "3.10.10"}

======================================================================
FAIL: test_required_relationships (nautobot.extras.tests.test_api.RelationshipTest) [Testing VLAN relationship 'vlans-devices-m2m']
1. Try creating an object when no required target object exists
----------------------------------------------------------------------
Traceback (most recent call last):
  File "/source/nautobot/extras/tests/test_relationships.py", line 1260, in required_relationships_test
    self.assertHttpStatus(response, 201)
  File "/source/nautobot/core/testing/mixins.py", line 166, in assertHttpStatus
    self.assertIn(response.status_code, expected_status, err_message)
AssertionError: 500 not found in [201] : Expected HTTP status(es) [201]; received 500: {"error": "'NoneType' object has no attribute 'Meta'", "exception": "AttributeError", "nautobot_version": "2.0.0a1", "python_version": "3.10.10"}

======================================================================
FAIL: test_required_relationships (nautobot.extras.tests.test_api.RelationshipTest) [Testing platform relationship 'platform-devices-o2m']
1. Try creating an object when no required target object exists
----------------------------------------------------------------------
Traceback (most recent call last):
  File "/source/nautobot/extras/tests/test_relationships.py", line 1203, in required_relationships_test
    self.assertHttpStatus(response, 400)
  File "/source/nautobot/core/testing/mixins.py", line 166, in assertHttpStatus
    self.assertIn(response.status_code, expected_status, err_message)
AssertionError: 500 not found in [400] : Expected HTTP status(es) [400]; received 500: {"error": "Platform() got an unexpected keyword argument 'slug'", "exception": "TypeError", "nautobot_version": "2.0.0a1", "python_version": "3.10.10"}

======================================================================
FAIL: test_required_relationships (nautobot.extras.tests.test_api.RelationshipTest) [Testing circuit type relationship 'circuittype-platform-o2o']
1. Try creating an object when no required target object exists
----------------------------------------------------------------------
Traceback (most recent call last):
  File "/source/nautobot/extras/tests/test_relationships.py", line 1203, in required_relationships_test
    self.assertHttpStatus(response, 400)
  File "/source/nautobot/core/testing/mixins.py", line 166, in assertHttpStatus
    self.assertIn(response.status_code, expected_status, err_message)
AssertionError: 500 not found in [400] : Expected HTTP status(es) [400]; received 500: {"error": "CircuitType() got an unexpected keyword argument 'slug'", "exception": "TypeError", "nautobot_version": "2.0.0a1", "python_version": "3.10.10"}

======================================================================
FAIL: test_required_relationships (nautobot.extras.tests.test_api.RelationshipTest)
1. Try creating an object when no required target object exists
----------------------------------------------------------------------
Traceback (most recent call last):
  File "/source/nautobot/extras/tests/test_api.py", line 2714, in test_required_relationships
    self.assertHttpStatus(response, 400)
  File "/source/nautobot/core/testing/mixins.py", line 166, in assertHttpStatus
    self.assertIn(response.status_code, expected_status, err_message)
AssertionError: 500 not found in [400] : Expected HTTP status(es) [400]; received 500: {"error": "'NoneType' object has no attribute 'Meta'", "exception": "AttributeError", "nautobot_version": "2.0.0a1", "python_version": "3.10.10"}

======================================================================
FAIL: test_create_tags_with_invalid_content_types (nautobot.extras.tests.test_api.TagTest)
----------------------------------------------------------------------
Traceback (most recent call last):
  File "/source/nautobot/extras/tests/test_api.py", line 3319, in test_create_tags_with_invalid_content_types
    self.assertHttpStatus(response, 400)
  File "/source/nautobot/core/testing/mixins.py", line 166, in assertHttpStatus
    self.assertIn(response.status_code, expected_status, err_message)
AssertionError: 500 not found in [400] : Expected HTTP status(es) [400]; received 500: {"error": "too many values to unpack (expected 2)", "exception": "ValueError", "nautobot_version": "2.0.0a1", "python_version": "3.10.10"}

======================================================================
FAIL: test_create_tags_without_content_types (nautobot.extras.tests.test_api.TagTest)
----------------------------------------------------------------------
Traceback (most recent call last):
  File "/source/nautobot/extras/tests/test_api.py", line 3331, in test_create_tags_without_content_types
    self.assertHttpStatus(response, 400)
  File "/source/nautobot/core/testing/mixins.py", line 166, in assertHttpStatus
    self.assertIn(response.status_code, expected_status, err_message)
AssertionError: 201 not found in [400] : Expected HTTP status(es) [400]; received 201: {'id': 'e09c3b7c-17e4-4f56-bd54-987e2d7bf32d', 'display': 'Tag 8', 'url': 'http://nautobot.example.com/api/extras/tags/e09c3b7c-17e4-4f56-bd54-987e2d7bf32d/', 'relationships': {}, 'computed_fields': {}, 'custom_fields': {}, 'notes_url': 'http://nautobot.example.com/api/extras/tags/e09c3b7c-17e4-4f56-bd54-987e2d7bf32d/notes/', 'content_types': [], 'name': 'Tag 8', 'slug': 'tag-8', 'created': '2023-04-06T17:59:57.909850Z', 'last_updated': '2023-04-06T17:59:57.909871Z', 'color': '9e9e9e', 'description': ''}

======================================================================
FAIL: test_create_object (nautobot.extras.tests.test_changelog.ChangeLogAPITest)
----------------------------------------------------------------------
Traceback (most recent call last):
  File "/source/nautobot/extras/tests/test_changelog.py", line 282, in test_create_object
    self.assertHttpStatus(response, status.HTTP_201_CREATED)
  File "/source/nautobot/core/testing/mixins.py", line 166, in assertHttpStatus
    self.assertIn(response.status_code, expected_status, err_message)
AssertionError: 500 not found in [201] : Expected HTTP status(es) [201]; received 500: {"error": "'NoneType' object has no attribute 'instance'", "exception": "AttributeError", "nautobot_version": "2.0.0a1", "python_version": "3.10.10"}

======================================================================
FAIL: test_update_object (nautobot.extras.tests.test_changelog.ChangeLogAPITest)
Test PUT with changelogs.
----------------------------------------------------------------------
Traceback (most recent call last):
  File "/source/nautobot/extras/tests/test_changelog.py", line 318, in test_update_object
    self.assertHttpStatus(response, status.HTTP_200_OK)
  File "/source/nautobot/core/testing/mixins.py", line 166, in assertHttpStatus
    self.assertIn(response.status_code, expected_status, err_message)
AssertionError: 500 not found in [200] : Expected HTTP status(es) [200]; received 500: {"error": "'NoneType' object has no attribute 'instance'", "exception": "AttributeError", "nautobot_version": "2.0.0a1", "python_version": "3.10.10"}

======================================================================
FAIL: test_bigint_values_of_custom_field_maximum_attribute (nautobot.extras.tests.test_customfields.CustomFieldDataAPITest)
----------------------------------------------------------------------
Traceback (most recent call last):
  File "/source/nautobot/extras/tests/test_customfields.py", line 817, in test_bigint_values_of_custom_field_maximum_attribute
    self.assertHttpStatus(response, status.HTTP_200_OK)
  File "/source/nautobot/core/testing/mixins.py", line 166, in assertHttpStatus
    self.assertIn(response.status_code, expected_status, err_message)
AssertionError: 500 not found in [200] : Expected HTTP status(es) [200]; received 500: {"error": "'NoneType' object has no attribute 'instance'", "exception": "AttributeError", "nautobot_version": "2.0.0a1", "python_version": "3.10.10"}

======================================================================
FAIL: test_bigint_values_of_custom_field_minimum_attribute (nautobot.extras.tests.test_customfields.CustomFieldDataAPITest)
----------------------------------------------------------------------
Traceback (most recent call last):
  File "/source/nautobot/extras/tests/test_customfields.py", line 832, in test_bigint_values_of_custom_field_minimum_attribute
    self.assertHttpStatus(response, status.HTTP_200_OK)
  File "/source/nautobot/core/testing/mixins.py", line 166, in assertHttpStatus
    self.assertIn(response.status_code, expected_status, err_message)
AssertionError: 500 not found in [200] : Expected HTTP status(es) [200]; received 500: {"error": "'NoneType' object has no attribute 'instance'", "exception": "AttributeError", "nautobot_version": "2.0.0a1", "python_version": "3.10.10"}

======================================================================
FAIL: test_create_multiple_objects_with_defaults (nautobot.extras.tests.test_customfields.CustomFieldDataAPITest)
Create three news locations with no specified custom field values and check that each received
----------------------------------------------------------------------
Traceback (most recent call last):
  File "/source/nautobot/extras/tests/test_customfields.py", line 640, in test_create_multiple_objects_with_defaults
    self.assertEqual(response_cf["text_cf"], self.cf_text.default)
AssertionError: None != 'foo'

======================================================================
FAIL: test_create_multiple_objects_with_values (nautobot.extras.tests.test_customfields.CustomFieldDataAPITest)
Create a three new locations, each with custom fields defined.
----------------------------------------------------------------------
Traceback (most recent call last):
  File "/source/nautobot/extras/tests/test_customfields.py", line 704, in test_create_multiple_objects_with_values
    self.assertHttpStatus(response, status.HTTP_201_CREATED)
  File "/source/nautobot/core/testing/mixins.py", line 166, in assertHttpStatus
    self.assertIn(response.status_code, expected_status, err_message)
AssertionError: 500 not found in [201] : Expected HTTP status(es) [201]; received 500: {"error": "'NoneType' object has no attribute 'instance'", "exception": "AttributeError", "nautobot_version": "2.0.0a1", "python_version": "3.10.10"}

======================================================================
FAIL: test_create_single_object_with_defaults (nautobot.extras.tests.test_customfields.CustomFieldDataAPITest)
Create a new location with no specified custom field values and check that it received the default values.
----------------------------------------------------------------------
Traceback (most recent call last):
  File "/source/nautobot/extras/tests/test_customfields.py", line 527, in test_create_single_object_with_defaults
    self.assertEqual(response_cf["text_cf"], self.cf_text.default)
AssertionError: None != 'foo'

======================================================================
FAIL: test_create_single_object_with_values (nautobot.extras.tests.test_customfields.CustomFieldDataAPITest)
Create a single new location with a value for each type of custom field.
----------------------------------------------------------------------
Traceback (most recent call last):
  File "/source/nautobot/extras/tests/test_customfields.py", line 574, in test_create_single_object_with_values
    self.assertHttpStatus(response, status.HTTP_201_CREATED)
  File "/source/nautobot/core/testing/mixins.py", line 166, in assertHttpStatus
    self.assertIn(response.status_code, expected_status, err_message)
AssertionError: 500 not found in [201] : Expected HTTP status(es) [201]; received 500: {"error": "'NoneType' object has no attribute 'instance'", "exception": "AttributeError", "nautobot_version": "2.0.0a1", "python_version": "3.10.10"}

======================================================================
FAIL: test_minimum_maximum_values_validation (nautobot.extras.tests.test_customfields.CustomFieldDataAPITest)
----------------------------------------------------------------------
Traceback (most recent call last):
  File "/source/nautobot/extras/tests/test_customfields.py", line 798, in test_minimum_maximum_values_validation
    self.assertHttpStatus(response, status.HTTP_400_BAD_REQUEST)
  File "/source/nautobot/core/testing/mixins.py", line 166, in assertHttpStatus
    self.assertIn(response.status_code, expected_status, err_message)
AssertionError: 500 not found in [400] : Expected HTTP status(es) [400]; received 500: {"error": "'NoneType' object has no attribute 'instance'", "exception": "AttributeError", "nautobot_version": "2.0.0a1", "python_version": "3.10.10"}

======================================================================
FAIL: test_regex_validation (nautobot.extras.tests.test_customfields.CustomFieldDataAPITest)
----------------------------------------------------------------------
Traceback (most recent call last):
  File "/source/nautobot/extras/tests/test_customfields.py", line 847, in test_regex_validation
    self.assertHttpStatus(response, status.HTTP_400_BAD_REQUEST)
  File "/source/nautobot/core/testing/mixins.py", line 166, in assertHttpStatus
    self.assertIn(response.status_code, expected_status, err_message)
AssertionError: 500 not found in [400] : Expected HTTP status(es) [400]; received 500: {"error": "'NoneType' object has no attribute 'instance'", "exception": "AttributeError", "nautobot_version": "2.0.0a1", "python_version": "3.10.10"}

======================================================================
FAIL: test_text_type_with_invalid_values (nautobot.extras.tests.test_customfields.CustomFieldDataAPITest)
Try and create a new location with an invalid value for a text type.
----------------------------------------------------------------------
Traceback (most recent call last):
  File "/source/nautobot/extras/tests/test_customfields.py", line 893, in test_text_type_with_invalid_values
    self.assertHttpStatus(response, status.HTTP_400_BAD_REQUEST)
  File "/source/nautobot/core/testing/mixins.py", line 166, in assertHttpStatus
    self.assertIn(response.status_code, expected_status, err_message)
AssertionError: 500 not found in [400] : Expected HTTP status(es) [400]; received 500: {"error": "'NoneType' object has no attribute 'instance'", "exception": "AttributeError", "nautobot_version": "2.0.0a1", "python_version": "3.10.10"}

======================================================================
FAIL: test_update_single_object_with_values (nautobot.extras.tests.test_customfields.CustomFieldDataAPITest)
Update an object with existing custom field values. Ensure that only the updated custom field values are
----------------------------------------------------------------------
Traceback (most recent call last):
  File "/source/nautobot/extras/tests/test_customfields.py", line 755, in test_update_single_object_with_values
    self.assertHttpStatus(response, status.HTTP_200_OK)
  File "/source/nautobot/core/testing/mixins.py", line 166, in assertHttpStatus
    self.assertIn(response.status_code, expected_status, err_message)
AssertionError: 500 not found in [200] : Expected HTTP status(es) [200]; received 500: {"error": "'NoneType' object has no attribute 'instance'", "exception": "AttributeError", "nautobot_version": "2.0.0a1", "python_version": "3.10.10"}

======================================================================
FAIL: test_create_invalid_tagged_item (nautobot.extras.tests.test_tags.TaggedItemTest)
Test creating a Location with a tag that does not include Location's Content type as its content_type
----------------------------------------------------------------------
Traceback (most recent call last):
  File "/source/nautobot/extras/tests/test_tags.py", line 119, in test_create_invalid_tagged_item
    self.assertHttpStatus(response, status.HTTP_400_BAD_REQUEST)
  File "/source/nautobot/core/testing/mixins.py", line 166, in assertHttpStatus
    self.assertIn(response.status_code, expected_status, err_message)
AssertionError: 500 not found in [400] : Expected HTTP status(es) [400]; received 500: {"error": "'str' object has no attribute 'items'", "exception": "AttributeError", "nautobot_version": "2.0.0a1", "python_version": "3.10.10"}

======================================================================
FAIL: test_create_tagged_item (nautobot.extras.tests.test_tags.TaggedItemTest)
----------------------------------------------------------------------
Traceback (most recent call last):
  File "/source/nautobot/extras/tests/test_tags.py", line 62, in test_create_tagged_item
    self.assertHttpStatus(response, status.HTTP_201_CREATED)
  File "/source/nautobot/core/testing/mixins.py", line 166, in assertHttpStatus
    self.assertIn(response.status_code, expected_status, err_message)
AssertionError: 500 not found in [201] : Expected HTTP status(es) [201]; received 500: {"error": "'str' object has no attribute 'items'", "exception": "AttributeError", "nautobot_version": "2.0.0a1", "python_version": "3.10.10"}

----------------------------------------------------------------------
Ran 2067 tests in 629.874s

FAILED (failures=35, errors=1, skipped=70)
Emptying test database...
Database emptied!
Preserving test database for alias 'default'...
[0m