Running docker compose command "ps --services --filter status=running"
Running docker compose command "exec nautobot coverage erase"
PYTHON_VER=3.11 \
docker compose \
    --project-name "nautobot" \
    --project-directory "/Users/hanlinmiao/Desktop/nautobot/development/" \
    -f "/Users/hanlinmiao/Desktop/nautobot/development/docker-compose.yml" \
    -f "/Users/hanlinmiao/Desktop/nautobot/development/docker-compose.postgres.yml" \
    -f "/Users/hanlinmiao/Desktop/nautobot/development/docker-compose.dev.yml" exec nautobot coverage erase
Running docker compose command "ps --services --filter status=running"
Running docker compose command "exec nautobot coverage run --module nautobot.core.cli test nautobot.dcim.tests 
--config=nautobot/core/tests/nautobot_config.py --cache-test-fixtures --keepdb"
PYTHON_VER=3.11 \
docker compose \
    --project-name "nautobot" \
    --project-directory "/Users/hanlinmiao/Desktop/nautobot/development/" \
    -f "/Users/hanlinmiao/Desktop/nautobot/development/docker-compose.yml" \
    -f "/Users/hanlinmiao/Desktop/nautobot/development/docker-compose.postgres.yml" \
    -f "/Users/hanlinmiao/Desktop/nautobot/development/docker-compose.dev.yml" exec nautobot coverage run \
    --module nautobot.core.cli test nautobot.dcim.tests \
    --config=nautobot/core/tests/nautobot_config.py \
    --cache-test-fixtures \
    --keepdb
Using NautobotPerformanceTestRunner to run tests ...
Found 3652 test(s).
Using existing test database for alias 'default'...








    Checking for duplicate records ...

    Checking for duplicate records ...

    Checking for duplicate records ...

    Checking for duplicate records ...

>>> Finding and removing any invalid or dangling Note objects ...


>>> Removal completed. 







[33;1mFlushing all existing data from the database "default"...[0m
[33;1mLoading factory data from file development/factory_dump.10bccb0bfd2b0650e800.json[0m
Installed 7450 object(s) from 1 fixture(s)
[32;1mDatabase default populated successfully![0m
System check identified some issues:

WARNINGS:
[33;1m<Settings "nautobot_config">: (nautobot.core.W005) STORAGE_CONFIG has been set but STORAGE_BACKEND is not defined. STORAGE_CONFIG will be ignored.[0m

System check identified 1 issue (0 silenced).
.......................................................ss...............................................................ss.........................................................................................................................ss.....................................................................................................................................................................s...................ss..............................ss.............................................................................................ss..........................................................s....s.....................................................................................................................................ss..........................................................................................................................................................................................ss.............................................................................................ss....................................................................................................................................................................ss........................................................................................................................................................................s.................s.................................s.......................................................................s.......s.................s.................s....................................................s........s.......s.......................................s....................s.........................s...................s................................s.......................................ssssssssss...............s................F....F........F........F........F.........F.....F.....F.........F......F.s....F........F.........F.............F..............F.........F.........F..........F...........F......F........F.........F........F..........F......F.......F........F........F....F................................................s.........s................................................................s................................................................s...............................................................................s................................................................s.......................................s.......................................s....................................................s............................................s.......................s........................................s.........s........................................s.................................................................s..........................................s.................................................................................................................s................................................................s................................................s..........................................s...................................s.........s........................................s................................................................s.......................................s................................................................s..........................................................................s.........................................s................................................................s........................................s........................................s..........................................s
======================================================================
FAIL: test_get_docs_url (nautobot.dcim.tests.test_models.CableTestCase.test_get_docs_url)
Check that `get_docs_url()` returns a valid static file path for this model.
----------------------------------------------------------------------
Traceback (most recent call last):
  File "/source/nautobot/core/testing/models.py", line 45, in test_get_docs_url
    self.assertIsNotNone(get_docs_url(self.model))
AssertionError: unexpectedly None

======================================================================
FAIL: test_get_docs_url (nautobot.dcim.tests.test_models.ConsolePortTemplateTestCase.test_get_docs_url)
Check that `get_docs_url()` returns a valid static file path for this model.
----------------------------------------------------------------------
Traceback (most recent call last):
  File "/source/nautobot/core/testing/models.py", line 45, in test_get_docs_url
    self.assertIsNotNone(get_docs_url(self.model))
AssertionError: unexpectedly None

======================================================================
FAIL: test_get_docs_url (nautobot.dcim.tests.test_models.ConsolePortTestCase.test_get_docs_url)
Check that `get_docs_url()` returns a valid static file path for this model.
----------------------------------------------------------------------
Traceback (most recent call last):
  File "/source/nautobot/core/testing/models.py", line 45, in test_get_docs_url
    self.assertIsNotNone(get_docs_url(self.model))
AssertionError: unexpectedly None

======================================================================
FAIL: test_get_docs_url (nautobot.dcim.tests.test_models.ConsoleServerPortTemplateTestCase.test_get_docs_url)
Check that `get_docs_url()` returns a valid static file path for this model.
----------------------------------------------------------------------
Traceback (most recent call last):
  File "/source/nautobot/core/testing/models.py", line 45, in test_get_docs_url
    self.assertIsNotNone(get_docs_url(self.model))
AssertionError: unexpectedly None

======================================================================
FAIL: test_get_docs_url (nautobot.dcim.tests.test_models.ConsoleServerPortTestCase.test_get_docs_url)
Check that `get_docs_url()` returns a valid static file path for this model.
----------------------------------------------------------------------
Traceback (most recent call last):
  File "/source/nautobot/core/testing/models.py", line 45, in test_get_docs_url
    self.assertIsNotNone(get_docs_url(self.model))
AssertionError: unexpectedly None

======================================================================
FAIL: test_get_docs_url (nautobot.dcim.tests.test_models.ControllerManagedDeviceGroupTestCase.test_get_docs_url)
Check that `get_docs_url()` returns a valid static file path for this model.
----------------------------------------------------------------------
Traceback (most recent call last):
  File "/source/nautobot/core/testing/models.py", line 45, in test_get_docs_url
    self.assertIsNotNone(get_docs_url(self.model))
AssertionError: unexpectedly None

======================================================================
FAIL: test_get_docs_url (nautobot.dcim.tests.test_models.ControllerTestCase.test_get_docs_url)
Check that `get_docs_url()` returns a valid static file path for this model.
----------------------------------------------------------------------
Traceback (most recent call last):
  File "/source/nautobot/core/testing/models.py", line 45, in test_get_docs_url
    self.assertIsNotNone(get_docs_url(self.model))
AssertionError: unexpectedly None

======================================================================
FAIL: test_get_docs_url (nautobot.dcim.tests.test_models.DeviceBayTestCase.test_get_docs_url)
Check that `get_docs_url()` returns a valid static file path for this model.
----------------------------------------------------------------------
Traceback (most recent call last):
  File "/source/nautobot/core/testing/models.py", line 45, in test_get_docs_url
    self.assertIsNotNone(get_docs_url(self.model))
AssertionError: unexpectedly None

======================================================================
FAIL: test_get_docs_url (nautobot.dcim.tests.test_models.DeviceTestCase.test_get_docs_url)
Check that `get_docs_url()` returns a valid static file path for this model.
----------------------------------------------------------------------
Traceback (most recent call last):
  File "/source/nautobot/core/testing/models.py", line 45, in test_get_docs_url
    self.assertIsNotNone(get_docs_url(self.model))
AssertionError: unexpectedly None

======================================================================
FAIL: test_software_version_device_type_validation (nautobot.dcim.tests.test_models.DeviceTestCase.test_software_version_device_type_validation)
Assert that device's software version contains a software image file that matches the device's device type or a default image.
----------------------------------------------------------------------
Traceback (most recent call last):
  File "/source/nautobot/dcim/tests/test_models.py", line 1728, in test_software_version_device_type_validation
    with self.assertRaises(ValidationError):
AssertionError: ValidationError not raised

======================================================================
FAIL: test_get_docs_url (nautobot.dcim.tests.test_models.FrontPortTemplateTestCase.test_get_docs_url)
Check that `get_docs_url()` returns a valid static file path for this model.
----------------------------------------------------------------------
Traceback (most recent call last):
  File "/source/nautobot/core/testing/models.py", line 45, in test_get_docs_url
    self.assertIsNotNone(get_docs_url(self.model))
AssertionError: unexpectedly None

======================================================================
FAIL: test_get_docs_url (nautobot.dcim.tests.test_models.FrontPortTestCase.test_get_docs_url)
Check that `get_docs_url()` returns a valid static file path for this model.
----------------------------------------------------------------------
Traceback (most recent call last):
  File "/source/nautobot/core/testing/models.py", line 45, in test_get_docs_url
    self.assertIsNotNone(get_docs_url(self.model))
AssertionError: unexpectedly None

======================================================================
FAIL: test_get_docs_url (nautobot.dcim.tests.test_models.InterfaceRedundancyGroupTestCase.test_get_docs_url)
Check that `get_docs_url()` returns a valid static file path for this model.
----------------------------------------------------------------------
Traceback (most recent call last):
  File "/source/nautobot/core/testing/models.py", line 45, in test_get_docs_url
    self.assertIsNotNone(get_docs_url(self.model))
AssertionError: unexpectedly None

======================================================================
FAIL: test_get_docs_url (nautobot.dcim.tests.test_models.InterfaceTestCase.test_get_docs_url)
Check that `get_docs_url()` returns a valid static file path for this model.
----------------------------------------------------------------------
Traceback (most recent call last):
  File "/source/nautobot/core/testing/models.py", line 45, in test_get_docs_url
    self.assertIsNotNone(get_docs_url(self.model))
AssertionError: unexpectedly None

======================================================================
FAIL: test_get_docs_url (nautobot.dcim.tests.test_models.LocationTestCase.test_get_docs_url)
Check that `get_docs_url()` returns a valid static file path for this model.
----------------------------------------------------------------------
Traceback (most recent call last):
  File "/source/nautobot/core/testing/models.py", line 45, in test_get_docs_url
    self.assertIsNotNone(get_docs_url(self.model))
AssertionError: unexpectedly None

======================================================================
FAIL: test_get_docs_url (nautobot.dcim.tests.test_models.ModuleBayTemplateTestCase.test_get_docs_url)
Check that `get_docs_url()` returns a valid static file path for this model.
----------------------------------------------------------------------
Traceback (most recent call last):
  File "/source/nautobot/core/testing/models.py", line 45, in test_get_docs_url
    self.assertIsNotNone(get_docs_url(self.model))
AssertionError: unexpectedly None

======================================================================
FAIL: test_get_docs_url (nautobot.dcim.tests.test_models.ModuleBayTestCase.test_get_docs_url)
Check that `get_docs_url()` returns a valid static file path for this model.
----------------------------------------------------------------------
Traceback (most recent call last):
  File "/source/nautobot/core/testing/models.py", line 45, in test_get_docs_url
    self.assertIsNotNone(get_docs_url(self.model))
AssertionError: unexpectedly None

======================================================================
FAIL: test_get_docs_url (nautobot.dcim.tests.test_models.ModuleTestCase.test_get_docs_url)
Check that `get_docs_url()` returns a valid static file path for this model.
----------------------------------------------------------------------
Traceback (most recent call last):
  File "/source/nautobot/core/testing/models.py", line 45, in test_get_docs_url
    self.assertIsNotNone(get_docs_url(self.model))
AssertionError: unexpectedly None

======================================================================
FAIL: test_get_docs_url (nautobot.dcim.tests.test_models.ModuleTypeTestCase.test_get_docs_url)
Check that `get_docs_url()` returns a valid static file path for this model.
----------------------------------------------------------------------
Traceback (most recent call last):
  File "/source/nautobot/core/testing/models.py", line 45, in test_get_docs_url
    self.assertIsNotNone(get_docs_url(self.model))
AssertionError: unexpectedly None

======================================================================
FAIL: test_get_docs_url (nautobot.dcim.tests.test_models.PowerOutletTemplateTestCase.test_get_docs_url)
Check that `get_docs_url()` returns a valid static file path for this model.
----------------------------------------------------------------------
Traceback (most recent call last):
  File "/source/nautobot/core/testing/models.py", line 45, in test_get_docs_url
    self.assertIsNotNone(get_docs_url(self.model))
AssertionError: unexpectedly None

======================================================================
FAIL: test_get_docs_url (nautobot.dcim.tests.test_models.PowerOutletTestCase.test_get_docs_url)
Check that `get_docs_url()` returns a valid static file path for this model.
----------------------------------------------------------------------
Traceback (most recent call last):
  File "/source/nautobot/core/testing/models.py", line 45, in test_get_docs_url
    self.assertIsNotNone(get_docs_url(self.model))
AssertionError: unexpectedly None

======================================================================
FAIL: test_get_docs_url (nautobot.dcim.tests.test_models.PowerPortTemplateTestCase.test_get_docs_url)
Check that `get_docs_url()` returns a valid static file path for this model.
----------------------------------------------------------------------
Traceback (most recent call last):
  File "/source/nautobot/core/testing/models.py", line 45, in test_get_docs_url
    self.assertIsNotNone(get_docs_url(self.model))
AssertionError: unexpectedly None

======================================================================
FAIL: test_get_docs_url (nautobot.dcim.tests.test_models.PowerPortTestCase.test_get_docs_url)
Check that `get_docs_url()` returns a valid static file path for this model.
----------------------------------------------------------------------
Traceback (most recent call last):
  File "/source/nautobot/core/testing/models.py", line 45, in test_get_docs_url
    self.assertIsNotNone(get_docs_url(self.model))
AssertionError: unexpectedly None

======================================================================
FAIL: test_get_docs_url (nautobot.dcim.tests.test_models.RackGroupTestCase.test_get_docs_url)
Check that `get_docs_url()` returns a valid static file path for this model.
----------------------------------------------------------------------
Traceback (most recent call last):
  File "/source/nautobot/core/testing/models.py", line 45, in test_get_docs_url
    self.assertIsNotNone(get_docs_url(self.model))
AssertionError: unexpectedly None

======================================================================
FAIL: test_get_docs_url (nautobot.dcim.tests.test_models.RackTestCase.test_get_docs_url)
Check that `get_docs_url()` returns a valid static file path for this model.
----------------------------------------------------------------------
Traceback (most recent call last):
  File "/source/nautobot/core/testing/models.py", line 45, in test_get_docs_url
    self.assertIsNotNone(get_docs_url(self.model))
AssertionError: unexpectedly None

======================================================================
FAIL: test_get_docs_url (nautobot.dcim.tests.test_models.RearPortTemplateTestCase.test_get_docs_url)
Check that `get_docs_url()` returns a valid static file path for this model.
----------------------------------------------------------------------
Traceback (most recent call last):
  File "/source/nautobot/core/testing/models.py", line 45, in test_get_docs_url
    self.assertIsNotNone(get_docs_url(self.model))
AssertionError: unexpectedly None

======================================================================
FAIL: test_get_docs_url (nautobot.dcim.tests.test_models.RearPortTestCase.test_get_docs_url)
Check that `get_docs_url()` returns a valid static file path for this model.
----------------------------------------------------------------------
Traceback (most recent call last):
  File "/source/nautobot/core/testing/models.py", line 45, in test_get_docs_url
    self.assertIsNotNone(get_docs_url(self.model))
AssertionError: unexpectedly None

======================================================================
FAIL: test_get_docs_url (nautobot.dcim.tests.test_models.SoftwareImageFileTestCase.test_get_docs_url)
Check that `get_docs_url()` returns a valid static file path for this model.
----------------------------------------------------------------------
Traceback (most recent call last):
  File "/source/nautobot/core/testing/models.py", line 45, in test_get_docs_url
    self.assertIsNotNone(get_docs_url(self.model))
AssertionError: unexpectedly None

======================================================================
FAIL: test_get_docs_url (nautobot.dcim.tests.test_models.SoftwareVersionTestCase.test_get_docs_url)
Check that `get_docs_url()` returns a valid static file path for this model.
----------------------------------------------------------------------
Traceback (most recent call last):
  File "/source/nautobot/core/testing/models.py", line 45, in test_get_docs_url
    self.assertIsNotNone(get_docs_url(self.model))
AssertionError: unexpectedly None

----------------------------------------------------------------------
Ran 3652 tests in 579.465s

FAILED (failures=29, skipped=82)
Emptying test database "default"...
Database default emptied!
Preserving test database for alias 'default'...
[0m